Test me
 * Serving Flask app "app" (lazy loading)
 * Environment: production
   WARNING: Do not use the development server in a production environment.
   Use a production WSGI server instead.
 * Debug mode: off
Traceback (most recent call last):
  File "app.py", line 11, in <module>
    app.run(host='0.0.0.0', port='80')
  File "/usr/local/lib/python2.7/dist-packages/flask/app.py", line 943, in run
    run_simple(host, port, self, **options)
  File "/usr/local/lib/python2.7/dist-packages/werkzeug/serving.py", line 814, in run_simple
    inner()
  File "/usr/local/lib/python2.7/dist-packages/werkzeug/serving.py", line 774, in inner
    fd=fd)
  File "/usr/local/lib/python2.7/dist-packages/werkzeug/serving.py", line 660, in make_server
    passthrough_errors, ssl_context, fd=fd)
  File "/usr/local/lib/python2.7/dist-packages/werkzeug/serving.py", line 577, in __init__
    self.address_family), handler)
  File "/usr/lib/python2.7/SocketServer.py", line 417, in __init__
    self.server_bind()
  File "/usr/lib/python2.7/BaseHTTPServer.py", line 108, in server_bind
    SocketServer.TCPServer.server_bind(self)
  File "/usr/lib/python2.7/SocketServer.py", line 431, in server_bind
    self.socket.bind(self.server_address)
  File "/usr/lib/python2.7/socket.py", line 228, in meth
    return getattr(self._sock,name)(*args)
socket.error: [Errno 13] Permission denied
 * Serving Flask app "app" (lazy loading)
 * Environment: production
   WARNING: Do not use the development server in a production environment.
   Use a production WSGI server instead.
 * Debug mode: on
Traceback (most recent call last):
  File "app.py", line 18, in <module>
    app.run(debug='true',host='0.0.0.0',port=port)	
  File "/usr/local/lib/python2.7/dist-packages/flask/app.py", line 943, in run
    run_simple(host, port, self, **options)
  File "/usr/local/lib/python2.7/dist-packages/werkzeug/serving.py", line 795, in run_simple
    s.bind(get_sockaddr(hostname, port, address_family))
  File "/usr/lib/python2.7/socket.py", line 228, in meth
    return getattr(self._sock,name)(*args)
socket.error: [Errno 98] Address already in use
